Workbook

Sheet Findings Criteria
A1: Rating criteria
B5: Rating criteria
B6: Finding | C6: Meaning
B7: Comply | C7: The requirement is implemented and working
B8: Partially implemented | C8: Some implementation exists, but it is incomplete
B9: Not implemented | C9: No implementation of the requirement
B12: Rating criteria in detail
B13: Finding | C13: Meaning | D13: Description
B14: Comply | C14: The requirement is implemented and working | D14: Objective evidence shows the requirement is implemented and operating,
D15: including documented information where the standard requires it.
B16: Partially implemented | C16: Some implementation exists, but it is incomplete | D16: Practice exists, but documented information the standard requires is missing, or
D17: documented information exists, but evidence shows it is not consistently applied, or
D18: only part of the requirement is addressed.
B19: Not implemented | C19: No implementation of the requirement | D19: There is no objective evidence that the requirement is implemented.
D20: A document alone, with no evidence of practice, is rated Partially implemented, never Comply.
B23: Notes
B24: Use these ratings for every question. "OFI" (opportunity for improvement) keeps its audit meaning and is not a gap-analysis rating.
B25: A gap-analysis finding is a gap, not a nonconformity: before implementation there is no ISMS that can fail to conform.
B26: Actions that close gaps are remedial actions. Corrective action (ISO/IEC 27001 10.2) applies to nonconformities in an operating ISMS.
B27: The plan and progress sheets use FILTER, XLOOKUP and TEXTBEFORE: Excel 2021 or Microsoft 365 is required.
B28: The Transition sheet is historical and not used in this workflow.

Sheet Gap Analysis Checklist
A1: MSM Gap Analysis Tool v2.0 · ISO/IEC 27001:2022 ISMS gap analysis checklist
A3: Ref. | B3: Clause No. | C3: Main Clauses | D3: ISO/IEC 27001:2022 questions | E3: Finding | F3: Objective evidence (Comply) | G3: High Level Cause | H3: Main root cause (Partially implemented) | I3: Proposed remedial action (Partially implemented) | J3: Main root cause (Not implemented) | K3: Proposed remedial action (Not implemented)
A4: 1 | B4: 4 | C4: 4. Context of the organization | D4: Context of the Organization
A5: 2 | B5: 4.1 | C5: 4. Context of the organization | D5: Understanding the organization and its context
A6: 3 | B6: Q1-4.1 | C6: 4. Context of the organization | D6: Has the organization identified external and internal issues that are relevant to its purpose and that affect its ability to achieve the intended outcomes of the ISMS?
A7: 4 | B7: Q2-4.1 (Amd 1) | C7: 4. Context of the organization | D7: Has the organization determined whether climate change is a relevant issue?
A8: 5 | B8: 4.2 | C8: 4. Context of the organization | D8: Understanding needs and expectations of interested parties
A9: 6 | B9: Q3-4.2 | C9: 4. Context of the organization | D9: Has the organization determined the interested parties (e.g., customers, regulators, partners) that are relevant to the ISMS, and the requirements of these parties (including legal, regulatory, and contractual requirements) with respect to information security?
A10: 7 | B10: Q4-4.2 (Amd 1) | C10: 4. Context of the organization | D10: Has the organization determined the existence of applicable requirements related to climate change from relevant interested parties?
A11: 8 | B11: 4.3 | C11: 4. Context of the organization | D11: Determining the scope of the information security management system
A12: 9 | B12: Q5-4.3 | C12: 4. Context of the organization | D12: Has the organization determined the Scope of the ISMS?
A13: 10 | B13: Q6-4.3.a | C13: 4. Context of the organization | D13: When defining the scope of the ISMS, has the organization considered the external and internal issues identified in 4.1?
A14: 11 | B14: Q7-4.3.b | C14: 4. Context of the organization | D14: When defining the ISMS scope, has the organization taken into account the information security requirements of interested parties identified in 4.2?
A15: 12 | B15: Q8-4.3.c | C15: 4. Context of the organization | D15: Has the organization considered interfaces and dependencies between in-scope activities and those performed by other parties when establishing the ISMS scope?
A16: 13 | B16: Q9-4.3 | C16: 4. Context of the organization | D16: Is the scope of the ISMS defined and available as documented information (including the boundaries and applicability of the ISMS)?
A17: 14 | B17: 4.4 | C17: 4. Context of the organization | D17: Information security management system
A18: 15 | B18: Q10-4.4 | C18: 4. Context of the organization | D18: Has the organization established, implemented, maintains, and continually improves an ISMS (including all necessary processes and their interactions) in accordance with ISO 27001 requirements?
A19: 16 | B19: 5 | C19: 5. Leadership | D19: Leadership
A20: 17 | B20: 5.1 | C20: 5. Leadership | D20: Leadership and commitment
A21: 18 | B21: Q11-5.1.a | C21: 5. Leadership | D21: Has top management ensured that the information security policy and objectives are established and are compatible with the organization’s strategic direction?
A22: 19 | B22: Q12-5.1.b | C22: 5. Leadership | D22: Has top management ensured the integration of ISMS requirements into the organization’s business processes?
A23: 20 | B23: Q13-5.1.c | C23: 5. Leadership | D23: Has top management ensured that the resources needed for the ISMS are available?
A24: 21 | B24: Q14-5.1.d | C24: 5. Leadership | D24: Has top management communicated the importance of effective information security management and of conforming to ISMS requirements?
A25: 22 | B25: Q15-5.1.e | C25: 5. Leadership | D25: Has top management ensured that the ISMS achieves its intended outcomes (i.e., information security objectives and risk mitigation)?
A26: 23 | B26: Q16-5.1.f | C26: 5. Leadership | D26: Is top management directing and supporting persons to contribute to the effectiveness of the ISMS?
A27: 24 | B27: Q17-5.1.g | C27: 5. Leadership | D27: Is top management promoting continual improvement of the ISMS?
A28: 25 | B28: Q18-5.1.h | C28: 5. Leadership | D28: Is top management supporting other relevant managers to demonstrate leadership in information security within their areas of responsibility?
A29: 26 | B29: 5.2 | C29: 5. Leadership | D29: Policy
A30: 27 | B30: Q19-5.2.a | C30: 5. Leadership | D30: Has top management established an information security policy that is appropriate to the purpose of the organization (i.e., aligned with the organization’s purpose, context, and goals)?
A31: 28 | B31: Q20-5.2.b | C31: 5. Leadership | D31: Does the information security policy include information security objectives or provide a framework for setting such objectives?
A32: 29 | B32: Q21-5.2.c | C32: 5. Leadership | D32: Does the policy include a commitment to satisfy applicable information security requirements (e.g. legal, regulatory, contractual and other requirements)?
A33: 30 | B33: Q22-5.2.d | C33: 5. Leadership | D33: Does the information security policy include a commitment to continual improvement of the ISMS?
A34: 31 | B34: Q23-5.2.e | C34: 5. Leadership | D34: Is the information security policy available as documented information (i.e., documented, approved, and kept on record)?
A35: 32 | B35: Q24-5.2.f | C35: 5. Leadership | D35: Is the information security policy communicated within the organization to all relevant employees and stakeholders?
A36: 33 | B36: Q25-5.2.g | C36: 5. Leadership | D36: Is the information security policy available to interested parties, as appropriate (e.g., published for customers or regulators, if required)?
A37: 34 | B37: 5.3 | C37: 5. Leadership | D37: Organizational roles, responsibilities and authorities
A38: 35 | B38: Q26-5.3 | C38: 5. Leadership | D38: Are the information security roles, responsibilities, and authorities for relevant roles clearly assigned and communicated within the organization?
A39: 36 | B39: Q27-5.3.a | C39: 5. Leadership | D39: Has top management assigned responsibility and authority for ensuring that the ISMS conforms to ISO 27001 requirements?
A40: 37 | B40: Q28-5.3.b | C40: 5. Leadership | D40: Has top management assigned responsibility and authority for reporting on the performance of the ISMS to top management?
A41: 38 | B41: 6 | C41: 6. Planning | D41: Planning
...

Sheet Gap Analysis Impl. plan
C1: ISO 27001:2022 ISMS- Gap Analysis Implementation Plan
A3: Ref. | B3: Clause No. | C3: Main Clauses | D3: Description of Gap Identified | E3: Rating | F3: Proposed remedial action (Partially implemented or Not implemented) | G3: Responsibilities & Resources | H3: Deliverables & Outputs | I3: Planned Start Date | J3: Planned Finish Date | K3: Activity Progress % | L3: Status | M3: Comments
A4: 1 | B4: {=_xlfn._xlws.FILTER('Gap Analysis Checklist'!B4:C1864,'Gap Analysis Checklist'!B4:B1864<>"")} | C4: 4. Context of the organization | D4: {=_xlfn._xlws.FILTER(IF('Gap Analysis Checklist'!$E$4:$E$1864='Findings Criteria'!$B$8,'Gap Analysis Checklist'!$H$4:$H$1864&"",IF('Gap Analysis Checklist'!$E$4:$E$1864='Findings Criteria'!$B$9,'Gap Analysis Checklist'!$J$4:$J$1864&"","")),'Gap Analysis Checklist'!$B$4:$B$1864<>"")} | E4: {=_xlfn._xlws.FILTER('Gap Analysis Checklist'!$E$4:$E$1864&"",'Gap Analysis Checklist'!$B$4:$B$1864<>"")} | F4: {=_xlfn._xlws.FILTER(IF('Gap Analysis Checklist'!$E$4:$E$1864='Findings Criteria'!$B$8,'Gap Analysis Checklist'!$I$4:$I$1864&"",IF('Gap Analysis Checklist'!$E$4:$E$1864='Findings Criteria'!$B$9,'Gap Analysis Checklist'!$K$4:$K$1864&"","")),'Gap Analysis Checklist'!$B$4:$B$1864<>"")} | K4: 0
A5: 2 | K5: 0
A6: 3 | K6: 0
A7: 4 | K7: 0
A8: 5 | K8: 0
A9: 6 | K9: 0
A10: 7 | K10: 0
A11: 8 | K11: 0
A12: 9 | K12: 0
A13: 10 | K13: 0
A14: 11 | K14: 0
A15: 12 | K15: 0
A16: 13 | K16: 0
... A244: 241 | K244: 0
A245: 242
A246: 243

Sheet Sub-Clauses Implementation
C1: Sub-Clauses Implementation
A3: Ref. | B3: Sub-Clause No. | C3: Sub- Clauses | D3: Planned Finish Date | E3: Activity Progress % | F3: Status | G3: Comments
A4: 1 | B4: 4.1 | C4: Understanding the organization and its context | D4: =IF(F4="completed"," ",_xlfn.XLOOKUP(B4,'Gap Analysis Impl. plan'!$B$4:$B$400,'Gap Analysis Impl. plan'!$J$4:$J$400,"No Planned Date")) | E4: =_xlfn.XLOOKUP(B4,'Gap Analysis Impl. plan'!$B$4:$B$400,'Gap Analysis Impl. plan'!$K$4:$K$400," ") | F4: =_xlfn.XLOOKUP(B4,'Gap Analysis Impl. plan'!$B$4:$B$400,'Gap Analysis Impl. plan'!$L$4:$L$400," ")
A5: 2 | B5: 4.2 | C5: Understanding needs and expectations of interested parties | D5: =IF(F5="completed"," ",_xlfn.XLOOKUP(B5,'Gap Analysis Impl. plan'!$B$4:$B$400,'Gap Analysis Impl. plan'!$J$4:$J$400,"No Planned Date")) | E5: =_xlfn.XLOOKUP(B5,'Gap Analysis Impl. plan'!$B$4:$B$400,'Gap Analysis Impl. plan'!$K$4:$K$400," ") | F5: =_xlfn.XLOOKUP(B5,'Gap Analysis Impl. plan'!$B$4:$B$400,'Gap Analysis Impl. plan'!$L$4:$L$400," ")
A6: 3 | B6: 4.3 | C6: Determining the scope of the information security management system | D6: =IF(F6="completed"," ",_xlfn.XLOOKUP(B6,'Gap Analysis Impl. plan'!$B$4:$B$400,'Gap Analysis Impl. plan'!$J$4:$J$400,"No Planned Date")) | E6: =_xlfn.XLOOKUP(B6,'Gap Analysis Impl. plan'!$B$4:$B$400,'Gap Analysis Impl. plan'!$K$4:$K$400," ") | F6: =_xlfn.XLOOKUP(B6,'Gap Analysis Impl. plan'!$B$4:$B$400,'Gap Analysis Impl. plan'!$L$4:$L$400," ")
A7: 4 | B7: 4.4 | C7: Information security management system | D7: =IF(F7="completed"," ",_xlfn.XLOOKUP(B7,'Gap Analysis Impl. plan'!$B$4:$B$400,'Gap Analysis Impl. plan'!$J$4:$J$400,"No Planned Date")) | E7: =_xlfn.XLOOKUP(B7,'Gap Analysis Impl. plan'!$B$4:$B$400,'Gap Analysis Impl. plan'!$K$4:$K$400," ") | F7: =_xlfn.XLOOKUP(B7,'Gap Analysis Impl. plan'!$B$4:$B$400,'Gap Analysis Impl. plan'!$L$4:$L$400," ")
A8: 5 | B8: 5.1 | C8: Leadership and commitment | D8: =IF(F8="completed"," ",_xlfn.XLOOKUP(B8,'Gap Analysis Impl. plan'!$B$4:$B$400,'Gap Analysis Impl. plan'!$J$4:$J$400,"No Planned Date")) | E8: =_xlfn.XLOOKUP(B8,'Gap Analysis Impl. plan'!$B$4:$B$400,'Gap Analysis Impl. plan'!$K$4:$K$400," ") | F8: =_xlfn.XLOOKUP(B8,'Gap Analysis Impl. plan'!$B$4:$B$400,'Gap Analysis Impl. plan'!$L$4:$L$400," ")
A9: 6 | B9: 5.2 | C9: Policy | D9: =IF(F9="completed"," ",_xlfn.XLOOKUP(B9,'Gap Analysis Impl. plan'!$B$4:$B$400,'Gap Analysis Impl. plan'!$J$4:$J$400,"No Planned Date")) | E9: =_xlfn.XLOOKUP(B9,'Gap Analysis Impl. plan'!$B$4:$B$400,'Gap Analysis Impl. plan'!$K$4:$K$400," ") | F9: =_xlfn.XLOOKUP(B9,'Gap Analysis Impl. plan'!$B$4:$B$400,'Gap Analysis Impl. plan'!$L$4:$L$400," ")
A10: 7 | B10: 5.3 | C10: Organizational roles, responsibilities and authorities | D10: =IF(F10="completed"," ",_xlfn.XLOOKUP(B10,'Gap Analysis Impl. plan'!$B$4:$B$400,'Gap Analysis Impl. plan'!$J$4:$J$400,"No Planned Date")) | E10: =_xlfn.XLOOKUP(B10,'Gap Analysis Impl. plan'!$B$4:$B$400,'Gap Analysis Impl. plan'!$K$4:$K$400," ") | F10: =_xlfn.XLOOKUP(B10,'Gap Analysis Impl. plan'!$B$4:$B$400,'Gap Analysis Impl. plan'!$L$4:$L$400," ")
A11: 8 | B11: 6.1 | C11: Actions to address risks and opportunities | D11: =IF(F11="completed"," ",_xlfn.XLOOKUP(B11,'Gap Analysis Impl. plan'!$B$4:$B$400,'Gap Analysis Impl. plan'!$J$4:$J$400,"No Planned Date")) | E11: =_xlfn.XLOOKUP(B11,'Gap Analysis Impl. plan'!$B$4:$B$400,'Gap Analysis Impl. plan'!$K$4:$K$400," ") | F11: =_xlfn.XLOOKUP(B11,'Gap Analysis Impl. plan'!$B$4:$B$400,'Gap Analysis Impl. plan'!$L$4:$L$400," ")
A12: 9 | B12: 6.2 | C12: Information security objectives and planning to achieve them | D12: =IF(F12="completed"," ",_xlfn.XLOOKUP(B12,'Gap Analysis Impl. plan'!$B$4:$B$400,'Gap Analysis Impl. plan'!$J$4:$J$400,"No Planned Date")) | E12: =_xlfn.XLOOKUP(B12,'Gap Analysis Impl. plan'!$B$4:$B$400,'Gap Analysis Impl. plan'!$K$4:$K$400," ") | F12: =_xlfn.XLOOKUP(B12,'Gap Analysis Impl. plan'!$B$4:$B$400,'Gap Analysis Impl. plan'!$L$4:$L$400," ")
A13: 10 | B13: 6.3 | C13: Planning of changes | D13: =IF(F13="completed"," ",_xlfn.XLOOKUP(B13,'Gap Analysis Impl. plan'!$B$4:$B$400,'Gap Analysis Impl. plan'!$J$4:$J$400,"No Planned Date")) | E13: =_xlfn.XLOOKUP(B13,'Gap Analysis Impl. plan'!$B$4:$B$400,'Gap Analysis Impl. plan'!$K$4:$K$400," ") | F13: =_xlfn.XLOOKUP(B13,'Gap Analysis Impl. plan'!$B$4:$B$400,'Gap Analysis Impl. plan'!$L$4:$L$400," ")
A14: 11 | B14: 7.1 | C14: Resources | D14: =IF(F14="completed"," ",_xlfn.XLOOKUP(B14,'Gap Analysis Impl. plan'!$B$4:$B$400,'Gap Analysis Impl. plan'!$J$4:$J$400,"No Planned Date")) | E14: =_xlfn.XLOOKUP(B14,'Gap Analysis Impl. plan'!$B$4:$B$400,'Gap Analysis Impl. plan'!$K$4:$K$400," ") | F14: =_xlfn.XLOOKUP(B14,'Gap Analysis Impl. plan'!$B$4:$B$400,'Gap Analysis Impl. plan'!$L$4:$L$400," ")
A15: 12 | B15: 7.2 | C15: Competence | D15: =IF(F15="completed"," ",_xlfn.XLOOKUP(B15,'Gap Analysis Impl. plan'!$B$4:$B$400,'Gap Analysis Impl. plan'!$J$4:$J$400,"No Planned Date")) | E15: =_xlfn.XLOOKUP(B15,'Gap Analysis Impl. plan'!$B$4:$B$400,'Gap Analysis Impl. plan'!$K$4:$K$400," ") | F15: =_xlfn.XLOOKUP(B15,'Gap Analysis Impl. plan'!$B$4:$B$400,'Gap Analysis Impl. plan'!$L$4:$L$400," ")
... A26: 23 | B26: 10.2 | C26: Nonconformity and corrective action | D26: =IF(F26="completed"," ",_xlfn.XLOOKUP(B26,'Gap Analysis Impl. plan'!$B$4:$B$400,'Gap Analysis Impl. plan'!$J$4:$J$400,"No Planned Date")) | E26: =_xlfn.XLOOKUP(B26,'Gap Analysis Impl. plan'!$B$4:$B$400,'Gap Analysis Impl. plan'!$K$4:$K$400," ") | F26: =_xlfn.XLOOKUP(B26,'Gap Analysis Impl. plan'!$B$4:$B$400,'Gap Analysis Impl. plan'!$L$4:$L$400," ")
A27: 24 | B27: Annex A.5 | C27: Organizational controls | D27: =IF(F27="completed"," ",_xlfn.XLOOKUP(B27,'Gap Analysis Impl. plan'!$B$4:$B$400,'Gap Analysis Impl. plan'!$J$4:$J$400,"No Planned Date")) | E27: =_xlfn.XLOOKUP(B27,'Gap Analysis Impl. plan'!$B$4:$B$400,'Gap Analysis Impl. plan'!$K$4:$K$400," ") | F27: =_xlfn.XLOOKUP(B27,'Gap Analysis Impl. plan'!$B$4:$B$400,'Gap Analysis Impl. plan'!$L$4:$L$400," ")
A28: 25 | B28: Annex A.6 | C28: People controls | D28: =IF(F28="completed"," ",_xlfn.XLOOKUP(B28,'Gap Analysis Impl. plan'!$B$4:$B$400,'Gap Analysis Impl. plan'!$J$4:$J$400,"No Planned Date")) | E28: =_xlfn.XLOOKUP(B28,'Gap Analysis Impl. plan'!$B$4:$B$400,'Gap Analysis Impl. plan'!$K$4:$K$400," ") | F28: =_xlfn.XLOOKUP(B28,'Gap Analysis Impl. plan'!$B$4:$B$400,'Gap Analysis Impl. plan'!$L$4:$L$400," ")
A29: 26 | B29: Annex A.7 | C29: Physical controls | D29: =IF(F29="completed"," ",_xlfn.XLOOKUP(B29,'Gap Analysis Impl. plan'!$B$4:$B$400,'Gap Analysis Impl. plan'!$J$4:$J$400,"No Planned Date")) | E29: =_xlfn.XLOOKUP(B29,'Gap Analysis Impl. plan'!$B$4:$B$400,'Gap Analysis Impl. plan'!$K$4:$K$400," ") | F29: =_xlfn.XLOOKUP(B29,'Gap Analysis Impl. plan'!$B$4:$B$400,'Gap Analysis Impl. plan'!$L$4:$L$400," ")
A30: 27 | B30: Annex A.8 | C30: Technological controls | D30: =IF(F30="completed"," ",_xlfn.XLOOKUP(B30,'Gap Analysis Impl. plan'!$B$4:$B$400,'Gap Analysis Impl. plan'!$J$4:$J$400,"No Planned Date")) | E30: =_xlfn.XLOOKUP(B30,'Gap Analysis Impl. plan'!$B$4:$B$400,'Gap Analysis Impl. plan'!$K$4:$K$400," ") | F30: =_xlfn.XLOOKUP(B30,'Gap Analysis Impl. plan'!$B$4:$B$400,'Gap Analysis Impl. plan'!$L$4:$L$400," ")

Sheet Main Clauses Implementation
C1: Main Clauses Implementation
A3: Ref. | B3: Clause No. | C3: Main Clauses | D3: Planned Finish Date | E3: Activity Progress % | F3: Status | G3: Comments
A4: 1 | B4: 4 | C4: 4. Context | D4: {=IF(F4="Completed"," ",IF(MAX(_xlfn._xlws.FILTER('Sub-Clauses Implementation'!$D$4:$D$26,VALUE(_xlfn.TEXTBEFORE('Sub-Clauses Implementation'!$B$4:$B$26,"."))=B4," "))=0," ",MAX(_xlfn._xlws.FILTER('Sub-Clauses Implementation'!$D$4:$D$26,VALUE(_xlfn.TEXTBEFORE('Sub-Clauses Implementation'!$B$4:$B$26,"."))=B4," "))))} -> 0 | E4: {=AVERAGE(_xlfn._xlws.FILTER('Sub-Clauses Implementation'!$E$4:E$26,VALUE(_xlfn.TEXTBEFORE('Sub-Clauses Implementation'!$B$4:$B$26,"."))=B4," "))} -> 0 | F4: =_xlfn.XLOOKUP(B4,'Gap Analysis Impl. plan'!$B$4:$B$400,'Gap Analysis Impl. plan'!$L$4:$L$400," ") -> 0
A5: 2 | B5: 5 | C5: 5. Leadership | D5: {=IF(F5="Completed"," ",IF(MAX(_xlfn._xlws.FILTER('Sub-Clauses Implementation'!$D$4:$D$26,VALUE(_xlfn.TEXTBEFORE('Sub-Clauses Implementation'!$B$4:$B$26,"."))=B5," "))=0," ",MAX(_xlfn._xlws.FILTER('Sub-Clauses Implementation'!$D$4:$D$26,VALUE(_xlfn.TEXTBEFORE('Sub-Clauses Implementation'!$B$4:$B$26,"."))=B5," "))))} -> 0 | E5: {=AVERAGE(_xlfn._xlws.FILTER('Sub-Clauses Implementation'!$E$4:E$26,VALUE(_xlfn.TEXTBEFORE('Sub-Clauses Implementation'!$B$4:$B$26,"."))=B5," "))} -> 0 | F5: =_xlfn.XLOOKUP(B5,'Gap Analysis Impl. plan'!$B$4:$B$400,'Gap Analysis Impl. plan'!$L$4:$L$400," ") -> 0
A6: 3 | B6: 6 | C6: 6. Planning | D6: {=IF(F6="Completed"," ",IF(MAX(_xlfn._xlws.FILTER('Sub-Clauses Implementation'!$D$4:$D$26,VALUE(_xlfn.TEXTBEFORE('Sub-Clauses Implementation'!$B$4:$B$26,"."))=B6," "))=0," ",MAX(_xlfn._xlws.FILTER('Sub-Clauses Implementation'!$D$4:$D$26,VALUE(_xlfn.TEXTBEFORE('Sub-Clauses Implementation'!$B$4:$B$26,"."))=B6," "))))} -> 0 | E6: {=AVERAGE(_xlfn._xlws.FILTER('Sub-Clauses Implementation'!$E$4:E$26,VALUE(_xlfn.TEXTBEFORE('Sub-Clauses Implementation'!$B$4:$B$26,"."))=B6," "))} -> 0 | F6: =_xlfn.XLOOKUP(B6,'Gap Analysis Impl. plan'!$B$4:$B$400,'Gap Analysis Impl. plan'!$L$4:$L$400," ") -> 0
A7: 4 | B7: 7 | C7: 7. Support | D7: {=IF(F7="Completed"," ",IF(MAX(_xlfn._xlws.FILTER('Sub-Clauses Implementation'!$D$4:$D$26,VALUE(_xlfn.TEXTBEFORE('Sub-Clauses Implementation'!$B$4:$B$26,"."))=B7," "))=0," ",MAX(_xlfn._xlws.FILTER('Sub-Clauses Implementation'!$D$4:$D$26,VALUE(_xlfn.TEXTBEFORE('Sub-Clauses Implementation'!$B$4:$B$26,"."))=B7," "))))} -> 0 | E7: {=AVERAGE(_xlfn._xlws.FILTER('Sub-Clauses Implementation'!$E$4:E$26,VALUE(_xlfn.TEXTBEFORE('Sub-Clauses Implementation'!$B$4:$B$26,"."))=B7," "))} -> 0 | F7: =_xlfn.XLOOKUP(B7,'Gap Analysis Impl. plan'!$B$4:$B$400,'Gap Analysis Impl. plan'!$L$4:$L$400," ") -> 0
A8: 5 | B8: 8 | C8: 8. Operation | D8: {=IF(F8="Completed"," ",IF(MAX(_xlfn._xlws.FILTER('Sub-Clauses Implementation'!$D$4:$D$26,VALUE(_xlfn.TEXTBEFORE('Sub-Clauses Implementation'!$B$4:$B$26,"."))=B8," "))=0," ",MAX(_xlfn._xlws.FILTER('Sub-Clauses Implementation'!$D$4:$D$26,VALUE(_xlfn.TEXTBEFORE('Sub-Clauses Implementation'!$B$4:$B$26,"."))=B8," "))))} -> 0 | E8: {=AVERAGE(_xlfn._xlws.FILTER('Sub-Clauses Implementation'!$E$4:E$26,VALUE(_xlfn.TEXTBEFORE('Sub-Clauses Implementation'!$B$4:$B$26,"."))=B8," "))} -> 0 | F8: =_xlfn.XLOOKUP(B8,'Gap Analysis Impl. plan'!$B$4:$B$400,'Gap Analysis Impl. plan'!$L$4:$L$400," ") -> 0
A9: 6 | B9: 9 | C9: 9. Evaluation | D9: {=IF(F9="Completed"," ",IF(MAX(_xlfn._xlws.FILTER('Sub-Clauses Implementation'!$D$4:$D$26,VALUE(_xlfn.TEXTBEFORE('Sub-Clauses Implementation'!$B$4:$B$26,"."))=B9," "))=0," ",MAX(_xlfn._xlws.FILTER('Sub-Clauses Implementation'!$D$4:$D$26,VALUE(_xlfn.TEXTBEFORE('Sub-Clauses Implementation'!$B$4:$B$26,"."))=B9," "))))} -> 0 | E9: {=AVERAGE(_xlfn._xlws.FILTER('Sub-Clauses Implementation'!$E$4:E$26,VALUE(_xlfn.TEXTBEFORE('Sub-Clauses Implementation'!$B$4:$B$26,"."))=B9," "))} -> 0 | F9: =_xlfn.XLOOKUP(B9,'Gap Analysis Impl. plan'!$B$4:$B$400,'Gap Analysis Impl. plan'!$L$4:$L$400," ") -> 0
A10: 7 | B10: 10 | C10: 10. Improvement | D10: {=IF(F10="Completed"," ",IF(MAX(_xlfn._xlws.FILTER('Sub-Clauses Implementation'!$D$4:$D$26,VALUE(_xlfn.TEXTBEFORE('Sub-Clauses Implementation'!$B$4:$B$26,"."))=B10," "))=0," ",MAX(_xlfn._xlws.FILTER('Sub-Clauses Implementation'!$D$4:$D$26,VALUE(_xlfn.TEXTBEFORE('Sub-Clauses Implementation'!$B$4:$B$26,"."))=B10," "))))} -> 0 | E10: {=AVERAGE(_xlfn._xlws.FILTER('Sub-Clauses Implementation'!$E$4:E$26,VALUE(_xlfn.TEXTBEFORE('Sub-Clauses Implementation'!$B$4:$B$26,"."))=B10," "))} -> 0 | F10: =_xlfn.XLOOKUP(B10,'Gap Analysis Impl. plan'!$B$4:$B$400,'Gap Analysis Impl. plan'!$L$4:$L$400," ") -> 0
A11: 8 | B11: Annex A. | C11: Annex A. Controls | D11: {=IF(F11="Completed"," ",IF(MAX(_xlfn._xlws.FILTER('Sub-Clauses Implementation'!$D$27:$D$30,VALUE(_xlfn.TEXTAFTER('Sub-Clauses Implementation'!$B$27:$B$30,"A."))))=0," ",MAX(_xlfn._xlws.FILTER('Sub-Clauses Implementation'!$D$27:$D$30,VALUE(_xlfn.TEXTAFTER('Sub-Clauses Implementation'!$B$27:$B$30,"A."))))))} -> 0 | E11: {=AVERAGE(_xlfn._xlws.FILTER('Sub-Clauses Implementation'!$E$27:E$30,VALUE(_xlfn.TEXTAFTER('Sub-Clauses Implementation'!$B$27:$B$30,"A."))))} -> 0 | F11: =_xlfn.XLOOKUP(B11,'Gap Analysis Impl. plan'!$B$4:$B$400,'Gap Analysis Impl. plan'!$L$4:$L$400," ") -> 0

Sheet Implementation Progress Charts 
B1: Implementation Progress- Charts

Sheet Transition (N-A, historical)
A1: Transition (not applicable)
A3: This sheet exists only to keep the MSM gap analysis tool family structure.
A4: The transition from ISO/IEC 27001:2013 to ISO/IEC 27001:2022 closed in October 2025.
A5: It is historical, not used in a new ISO/IEC 27001:2022 implementation, and excluded from all progress calculations.
